Workbook

Sheet Account - Clinical Data
A1: Study ID | B1: Hospital Account # | C1: DOB | D1: Age at enrollment | E1: Sex | F1: Scores Dates | K1: Optimization Duration (days) | L1: Surgery | N1: PRIMARY OUTCOMES — 30 DAYS | V1: SECONDARY OUTCOMES | AC1: Administrative
F2: First F2F score | H2: Reassesment | I2: Preoperative F2F score | L2: Debridements # | M2: Type of flap | N2: Complete Flap Failure (>75% loss) | O2: Partial Flap Failure (>25% flap loss) | P2: Deep SSI | Q2: Hematoma/Seroma → OR | R2: Major Dehiscence → OR | S2: 30-day Mortality | T2: ◉ PRIMARY ENDPOINT | U2: Clavien-Dindo Grade | V2: Minor Complication? | W2: Minor Comp Detail | X2: 30-day Readmission | Y2: 30-day Reoperation | Z2: LOS since enrollment (days) | AA2: ICU Admission | AB2: 90-day Recurrence | AC2: 30-day F/U Done? | AD2: 90-day F/U Done? | AE2: Notes

Sheet Instructions
A1: F2F SCORE — DATA COLLECTION INSTRUCTIONS
A2: HOW TO USE THIS SPREADSHEET
A3: 1. Open 'Patient Data' tab | B3: Enter one patient per row, starting at row 3.
A4: 2. Study ID | B4: Enter as LCH-001, PGH-002, DMC-003, depending of hospital: DMC Delray, LCH Larkin, PGH Plametto, etc. Must be unique and de-identified — NO patient names. | C4: HIPAA: de-identified only
A5: 3. Enrollment Date | B5: Date the F2F Score was first calculated for this patient.
A6: 4. Surgery Date | B6: Date of the index flap reconstruction procedure.
A7: 5. Pre-Screen (columns J–R) | B7: Check each absolute contraindication — Y if present, N if absent. Column S auto-calculates. If 'STOP' appears, do not score.
A8: 6. Domain 1–4 Entry | B8: Select from dropdown for each variable. Gray 'Pts' columns calculate automatically — do not edit. | C8: Do NOT edit gray columns
A9: 7. F2F Total Score (col BI) | B9: Calculates automatically from domain totals. | C9: Auto-calculated
A10: 8. Risk Tier (col BJ) | B10: Calculates automatically and color-codes: Green=Low, Yellow=Moderate, Orange=High, Red=Not Ideal. | C10: Auto-calculated
A11: 9. Infection Concern (col T) | B11: If No: PCT and inflammatory markers score 0 automatically.
A12: 10. PVD (col AP) | B12: Only relevant for lower extremity or multiple site wounds — auto-scored 0 otherwise.
A14: OUTCOME COLLECTION
A15: 11. Primary Endpoint (col CB) | B15: Auto-calculates: 'YES — EVENT' if ANY of columns BU–CA = Y. | C15: Blinded adjudication required
A16: 12. Adjudicator ID (col CK) | B16: Enter the ID of the co-investigator who adjudicated the 30-day endpoint (must be blinded to F2F Score). | C16: Protocol requirement
A17: 13. 90-day Recurrence (col CJ) | B17: Pressure injury cases only — leave blank for other indications.
A18: 14. F/U Complete (cols CM, CN) | B18: Mark Y when 30-day and 90-day follow-up data collection is complete for this patient.
A20: DATA INTEGRITY
A21: 15. Do not edit gray cells | B21: Gray cells contain auto-calculated formulas. Editing them will break the scoring.
A22: 16. De-identified data only | B22: Never enter patient name, date of birth, MRN, address, or any other PHI. | C22: HIPAA requirement
A23: 17. Dashboard tab | B23: Auto-updates with enrollment counts and event rates as you enter data.
A24: 18. Reference tab | B24: Complete F2F scoring guide for reference during data entry.
A26: CONTACT
A27: Principal Investigator | B27: Pedro Fuenmayor, MD — Larkin Community Hospital Plastic Surgery Program
A28: Protocol Version | B28: 1.0 — See IRB approval documents for current protocol version.

Sheet Clavien-Dindo Ref
A1: Clavien-Dindo Classification of Surgical Complications
A2: Grade | B2: Definition
A3: I | B3: Any deviation from the normal postoperative course without the need for pharmacological treatment or surgical, endoscopic, and radiological interventions. Allowed therapeutic regimens are: drugs as antiemetics, antipyretics, analgesics, diuretics, electrolytes, and physiotherapy. This grade also includes wound infections opened at the bedside.
A4: II | B4: Requiring pharmacological treatment with drugs other than those allowed for Grade I complications. Blood transfusions and total parenteral nutrition are also included.
A5: IIIa | B5: Requiring surgical, endoscopic or radiological intervention not under general anesthesia.
A6: IIIb | B6: Requiring surgical, endoscopic or radiological intervention under general anesthesia.
A7: IVa | B7: Life-threatening complication (including CNS complications) requiring IC/ICU management - single organ dysfunction.
A8: IVb | B8: Life-threatening complication (including CNS complications) requiring IC/ICU management - multiorgan dysfunction.
A9: V | B9: Death of a patient.
A11: Suffix 'd' | B11: If the patient suffers from a complication at the time of discharge, the suffix 'd' (for disability) is added to the respective grade of complication. This label indicates the need for a follow-up to fully evaluate the complication.

Sheet Dashboard
A1: F2F STUDY — ENROLLMENT DASHBOARD
A2: METRIC | B2: VALUE | C2: NOTES
A3: Total Patients Enrolled | B3: =COUNTA('Don’t use Patient Data'!A3:A202) -> 0 | C3: Auto-updates
A4: Surgery Performed | B4: =COUNTA('Don’t use Patient Data'!C3:C202) -> 0 | C4: Auto-updates
A5: 30-day F/U Complete | B5: =COUNTIF('Don’t use Patient Data'!CN3:CN202,"Y") -> 0
A6: 90-day F/U Complete | B6: =COUNTIF('Don’t use Patient Data'!CO3:CO202,"Y") -> 0
A7: Primary Endpoint Events (YES) | B7: =COUNTIF('Don’t use Patient Data'!CC3:CC202,"YES — EVENT") -> 0
A8: Event Rate (%) | B8: =IFERROR(COUNTIF('Don’t use Patient Data'!CC3:CC202,"YES — EVENT")/COUNTIF('Don’t use Patient Data'!CN3:CN202,"Y")*100,"—") -> — | C8: Events / 30d F/U complete
A10: BY RISK TIER
A11: LOW RISK patients | B11: =COUNTIF('Don’t use Patient Data'!BK3:BK202,"LOW RISK") -> 200 | C11: F2F 0–5 pts
A12: MODERATE RISK patients | B12: =COUNTIF('Don’t use Patient Data'!BK3:BK202,"MODERATE RISK") -> 0 | C12: F2F 6–12 pts
A13: HIGH RISK patients | B13: =COUNTIF('Don’t use Patient Data'!BK3:BK202,"HIGH RISK") -> 0 | C13: F2F 13–19 pts
A14: NOT IDEAL CANDIDATE | B14: =COUNTIF('Don’t use Patient Data'!BK3:BK202,"NOT AN IDEAL CANDIDATE") -> 0 | C14: F2F ≥20 pts
A16: OPTIMIZATION
A17: Patients who received pre-op optimization | B17: =COUNTIF('Don’t use Patient Data'!BR3:BR202,"Y") -> 0
A18: Abs CI present at enrollment | B18: =COUNTIF('Don’t use Patient Data'!T3:T202,"STOP — ABS CI PRESENT") -> 0
A20: DATA QUALITY
A21: Records missing surgery date | B21: =COUNTIF('Don’t use Patient Data'!A3:A202,"<>")-COUNTA('Don’t use Patient Data'!C3:C202) -> 0
A22: Missing 30-day F/U | B22: =COUNTA('Don’t use Patient Data'!C3:C202)-COUNTIF('Don’t use Patient Data'!CN3:CN202,"Y") -> 0

Sheet F2F Reference
A1: F2F SCORE — COMPLETE SCORING REFERENCE
A2: DOMAIN 1 — BIOMARKERS & NUTRITION (Max 9 pts)
A3: Variable | B3: Options | C3: Points | D3: Notes
A4: Albumin | B4: ≥3.5 g/dL / 3.0–3.49 g/dL / 2.5–2.99 g/dL / <2.5 (Abs CI) | C4: 0 / 1 / 3 / CI
A5: Prealbumin | B5: ≥18 mg/dL / 12–17.9 mg/dL / <12 mg/dL | C5: 0 / 1 / 2
A6: BMI / Weight Loss | B6: Normal / Borderline / Severe | C6: 0 / 1 / 3
A7: PCT (if infection concern) | B7: <0.5 / 0.5–2.0 / >2.0 ng/mL | C7: 0 / 1 / CI
A8: CRP>100 or WBC≥12k (if infection concern) | B8: Present / Absent | C8: 1 / 0
A10: DOMAIN 2 — WOUND FACTORS (Max 10 pts)
A11: Variable | B11: Options | C11: Points | D11: Notes
A12: Wound Location | B12: Sacral/Troch/Other / Multiple Sites / Ischial | C12: 0 / 1 / 3
A13: Wound Size | B13: <50 cm² / 50–100 cm² / >100 cm² | C13: 0 / 1 / 2
A14: Osteomyelitis | B14: None / Chronic + sequestrum / Acute purulent | C14: 0 / 1 / 3
A15: Prior Flap at Site | B15: None / 1 prior / ≥2 prior | C15: 0 / 2 / 3
A16: Wound Soiling | B16: None / Intermittent / Constant | C16: 0 / 1 / 2
A17: PVD (extremity wounds only) | B17: ABI <0.8 or absent pulses | C17: 0 or 1
A18: Irradiated Wound Bed | B18: Yes / No | C18: 1 / 0
A20: DOMAIN 3 — COMORBIDITIES (Max 6 pts)
A21: Variable | B21: Options | C21: Points | D21: Notes
A22: Diabetes (HbA1c) | B22: <7.0% / 7.0–7.9% / ≥8.0% | C22: 0 / 1 / 2
A23: Smoking | B23: Never/Former >6mo / Current or <6mo | C23: 0 / 2
A24: Cardiopulmonary / Renal | B24: None / 1 stable / ≥2 or symptomatic | C24: 0 / 1 / 2
A25: Chronic Steroids | B25: ≥30 days of >20 mg/day prednisone equiv. | C25: 0 or 2
A27: DOMAIN 4 — FUNCTIONAL & SOCIAL (Max 5 pts)
A28: Variable | B28: Options | C28: Points | D28: Notes
A29: Offloading Status | B29: Ambulatory / Wheelchair / Bedbound+mattress / Bedbound no mattress | C29: 0/1/2/3
A30: Social Support | B30: Reliable 24/7 / Inconsistent / None (Functional CI) | C30: 0 / 2 / CI
A32: RISK TIERS & RECOMMENDED ACTION
A33: LOW RISK | B33: 0–5 pts | C33: Proceed with flap reconstruction. Standard perioperative care.
A34: MODERATE RISK | B34: 6–12 pts | C34: Proceed after targeted optimization (1–2 weeks).
A35: HIGH RISK | B35: 13–19 pts | C35: Delay flap. Aggressive multidisciplinary optimization (2–4 weeks). Re-score.
A36: NOT AN IDEAL CANDIDATE | B36: ≥20 pts | C36: Avoid major flap. Palliative and advanced wound care strategies.

Sheet Don’t use Patient Data
A1: PATIENT INFORMATION | K1: PRE-SCREEN — ABSOLUTE CONTRAINDICATIONS | U1: DOMAIN 1 — BIOMARKERS & NUTRITION | AG1: DOMAIN 2 — WOUND FACTORS | AV1: DOMAIN 3 — COMORBIDITIES | BE1: DOMAIN 4 — FUNCTIONAL & SOCIAL | BJ1: F2F SCORE SUMMARY | BM1: OPERATIVE DETAILS | BR1: PRE-OPERATIVE OPTIMIZATION
A2: Study ID | B2: Enrollment Date | C2: Surgery Date | D2: Age (yrs) | E2: Sex | F2: Race / Ethnicity | H2: ASA Class | I2: Indication | J2: Planned Flap | K2: Debridements # | L2: Type of flap | M2: Coagulopathy | N2: Recent MI / Cardiac | O2: Metabolic Derangements | P2: Active Wound Infection | Q2: Severe PVD No Revasc | R2: No Realistic Support | S2: Palliative Goals | T2: ⚠ ABS CI STATUS | U2: Infection Concern? | V2: Albumin | W2: Pts | X2: Prealbumin | Y2: Pts | Z2: BMI / Weight Loss | AA2: Pts | AB2: PCT / Sepsis | AC2: Pts | AD2: CRP>100 or WBC≥12k? | AE2: Pts | AF2: D1 TOTAL | AG2: Wound Location | AH2: Pts | AI2: Wound Size | AJ2: Pts | AK2: Osteomyelitis | AL2: Pts | AM2: Prior Flap at Site | AN2: Pts | AO2: Wound Soiling | AP2: Pts | AQ2: PVD (extremity only) | AR2: Pts | AS2: Irradiated Bed? | AT2: Pts | AU2: D2 TOTAL | AV2: Diabetes / HbA1c | AW2: Pts | AX2: Smoking Status | AY2: Pts | AZ2: Cardiopulmonary / Renal | BA2: Pts | BB2: Chronic Steroids? | BC2: Pts | BD2: D3 TOTAL | BE2: Offloading Status | BF2: Pts | BG2: Social Support | BH2: Pts | BI2: D4 TOTAL | BJ2: F2F TOTAL SCORE | BK2: RISK TIER | BL2: CI Flags | BM2: Flap Performed | BN2: Donor Site | BO2: Op Time (min) | BP2: EBL (mL) | BQ2: Anesthesia | BR2: Pre-op Optimization? | BS2: Optim Duration (days) | BT2: Post-optim F2F Score | BU2: Post-optim Tier
H3: - | K3: 1 | T3: =IF(COUNTIF(K3:S3,"Y")>0,"STOP — ABS CI PRESENT","✓ Clear to Score") -> ✓ Clear to Score | W3: =IFERROR(IF(V3="","",IF(V3="≥3.5 g/dL",0,IF(V3="3.0-3.49 g/dL",1,IF(V3="2.5-2.99 g/dL",3,0)))),"") | Y3: =IFERROR(IF(X3="","",IF(X3="≥18 mg/dL",0,IF(X3="12-17.9 mg/dL",1,2))),"") | AA3: =IFERROR(IF(Z3="","",IF(ISNUMBER(SEARCH("Normal",Z3)),0,IF(ISNUMBER(SEARCH("Borderline",Z3)),1,3))),"") | AC3: =IFERROR(IF(U3="N",0,IF(AB3="","",IF(AB3="0.5-2.0 ng/mL",1,0))),"") | AE3: =IFERROR(IF(U3="N",0,IF(AD3="Y",1,0)),"") -> 0 | AF3: =IFERROR(SUM(W3,Y3,AA3,AC3,AE3),"") -> 0 | AH3: =IFERROR(IF(AG3="","",IF(AG3="Ischial",3,IF(AG3="Multiple Sites",1,0))),"") | AJ3: =IFERROR(IF(AI3="","",IF(AI3="<50 cm²",0,IF(AI3="50-100 cm²",1,2))),"") | AL3: =IFERROR(IF(AK3="","",IF(AK3="None",0,IF(AK3="Chronic (>4wk + sequestrum/sinus)",1,3))),"") | AN3: =IFERROR(IF(AM3="","",IF(AM3="None",0,IF(AM3="1 prior flap",2,3))),"") | AP3: =IFERROR(IF(AO3="","",IF(AO3="None",0,IF(AO3="Intermittent (not daily)",1,2))),"") | AR3: =IFERROR(IF(OR(AG3="Lower Extremity",AG3="Multiple Sites"),IF(AQ3="Y",1,0),0),"") -> 0 | AT3: =IFERROR(IF(AS3="Y",1,0),"") -> 0 | AU3: =IFERROR(SUM(AH3,AJ3,AL3,AN3,AP3,AR3,AT3),"") -> 0 | AW3: =IFERROR(IF(AV3="","",IF(AV3="No diabetes / HbA1c <7.0%",0,IF(AV3="HbA1c 7.0-7.9%",1,2))),"") | AY3: =IFERROR(IF(AX3="","",IF(AX3="Never / Former (>6mo abstinence)",0,2)),"") | BA3: =IFERROR(IF(AZ3="","",IF(AZ3="None",0,IF(AZ3="One stable condition",1,2))),"") | BC3: =IFERROR(IF(BB3="Y",2,0),"") -> 0 | BD3: =IFERROR(SUM(AW3,AY3,BA3,BC3),"") -> 0 | BF3: =IFERROR(IF(BE3="","",IF(BE3="Ambulatory",0,IF(BE3="Wheelchair w/ cushions",1,IF(BE3="Bedbound w/ offloading mattress",2,3)))),"") | BH3: =IFERROR(IF(BG3="","",IF(BG3="Reliable 24/7 care",0,IF(BG3="Some support — inconsistent",2,0))),"") | BI3: =IFERROR(SUM(BF3,BH3),"") -> 0 | BJ3: =IFERROR(IF(COUNTA(AF3,AU3,BD3,BI3)=0,"",SUM(AF3,AU3,BD3,BI3)),"") -> 0 | BK3: =IFERROR(IF(BJ3="","",IF(BJ3<6,"LOW RISK",IF(BJ3<13,"MODERATE RISK",IF(BJ3<20,"HIGH RISK","NOT AN IDEAL CANDIDATE")))),"") -> LOW RISK | BL3: =IFERROR(_xlfn.SINGLE(_xlfn.TEXTJOIN(", ", TRUE(), IF(V3 = "<2.5 g/dL (Abs CI)", "Albumin CI", ""), IF(AB3 = ">2.0 or Sepsis (Abs CI)", "PCT CI", ""), IF(BG3 = "No support (Functional CI)", "Functional CI", ""))), "") | BU3: =IFERROR(IF(BT3="","",IF(BT3<6,"LOW RISK",IF(BT3<13,"MODERATE RISK",IF(BT3<20,"HIGH RISK","NOT AN IDEAL CANDIDATE")))),"")
H4: - | K4: 2 | T4: =IF(COUNTIF(K4:S4,"Y")>0,"STOP — ABS CI PRESENT","✓ Clear to Score") -> ✓ Clear to Score | W4: =IFERROR(IF(V4="","",IF(V4="≥3.5 g/dL",0,IF(V4="3.0-3.49 g/dL",1,IF(V4="2.5-2.99 g/dL",3,0)))),"") | Y4: =IFERROR(IF(X4="","",IF(X4="≥18 mg/dL",0,IF(X4="12-17.9 mg/dL",1,2))),"") | AA4: =IFERROR(IF(Z4="","",IF(ISNUMBER(SEARCH("Normal",Z4)),0,IF(ISNUMBER(SEARCH("Borderline",Z4)),1,3))),"") | AC4: =IFERROR(IF(U4="N",0,IF(AB4="","",IF(AB4="0.5-2.0 ng/mL",1,0))),"") | AE4: =IFERROR(IF(U4="N",0,IF(AD4="Y",1,0)),"") -> 0 | AF4: =IFERROR(SUM(W4,Y4,AA4,AC4,AE4),"") -> 0 | AH4: =IFERROR(IF(AG4="","",IF(AG4="Ischial",3,IF(AG4="Multiple Sites",1,0))),"") | AJ4: =IFERROR(IF(AI4="","",IF(AI4="<50 cm²",0,IF(AI4="50-100 cm²",1,2))),"") | AL4: =IFERROR(IF(AK4="","",IF(AK4="None",0,IF(AK4="Chronic (>4wk + sequestrum/sinus)",1,3))),"") | AN4: =IFERROR(IF(AM4="","",IF(AM4="None",0,IF(AM4="1 prior flap",2,3))),"") | AP4: =IFERROR(IF(AO4="","",IF(AO4="None",0,IF(AO4="Intermittent (not daily)",1,2))),"") | AR4: =IFERROR(IF(OR(AG4="Lower Extremity",AG4="Multiple Sites"),IF(AQ4="Y",1,0),0),"") -> 0 | AT4: =IFERROR(IF(AS4="Y",1,0),"") -> 0 | AU4: =IFERROR(SUM(AH4,AJ4,AL4,AN4,AP4,AR4,AT4),"") -> 0 | AW4: =IFERROR(IF(AV4="","",IF(AV4="No diabetes / HbA1c <7.0%",0,IF(AV4="HbA1c 7.0-7.9%",1,2))),"") | AY4: =IFERROR(IF(AX4="","",IF(AX4="Never / Former (>6mo abstinence)",0,2)),"") | BA4: =IFERROR(IF(AZ4="","",IF(AZ4="None",0,IF(AZ4="One stable condition",1,2))),"") | BC4: =IFERROR(IF(BB4="Y",2,0),"") -> 0 | BD4: =IFERROR(SUM(AW4,AY4,BA4,BC4),"") -> 0 | BF4: =IFERROR(IF(BE4="","",IF(BE4="Ambulatory",0,IF(BE4="Wheelchair w/ cushions",1,IF(BE4="Bedbound w/ offloading mattress",2,3)))),"") | BH4: =IFERROR(IF(BG4="","",IF(BG4="Reliable 24/7 care",0,IF(BG4="Some support — inconsistent",2,0))),"") | BI4: =IFERROR(SUM(BF4,BH4),"") -> 0 | BJ4: =IFERROR(IF(COUNTA(AF4,AU4,BD4,BI4)=0,"",SUM(AF4,AU4,BD4,BI4)),"") -> 0 | BK4: =IFERROR(IF(BJ4="","",IF(BJ4<6,"LOW RISK",IF(BJ4<13,"MODERATE RISK",IF(BJ4<20,"HIGH RISK","NOT AN IDEAL CANDIDATE")))),"") -> LOW RISK | BL4: =IFERROR(_xlfn.SINGLE(_xlfn.TEXTJOIN(", ", TRUE(), IF(V4 = "<2.5 g/dL (Abs CI)", "Albumin CI", ""), IF(AB4 = ">2.0 or Sepsis (Abs CI)", "PCT CI", ""), IF(BG4 = "No support (Functional CI)", "Functional CI", ""))), "") | BU4: =IFERROR(IF(BT4="","",IF(BT4<6,"LOW RISK",IF(BT4<13,"MODERATE RISK",IF(BT4<20,"HIGH RISK","NOT AN IDEAL CANDIDATE")))),"")
T5: =IF(COUNTIF(K5:S5,"Y")>0,"STOP — ABS CI PRESENT","✓ Clear to Score") -> ✓ Clear to Score | W5: =IFERROR(IF(V5="","",IF(V5="≥3.5 g/dL",0,IF(V5="3.0-3.49 g/dL",1,IF(V5="2.5-2.99 g/dL",3,0)))),"") | Y5: =IFERROR(IF(X5="","",IF(X5="≥18 mg/dL",0,IF(X5="12-17.9 mg/dL",1,2))),"") | AA5: =IFERROR(IF(Z5="","",IF(ISNUMBER(SEARCH("Normal",Z5)),0,IF(ISNUMBER(SEARCH("Borderline",Z5)),1,3))),"") | AC5: =IFERROR(IF(U5="N",0,IF(AB5="","",IF(AB5="0.5-2.0 ng/mL",1,0))),"") | AE5: =IFERROR(IF(U5="N",0,IF(AD5="Y",1,0)),"") -> 0 | AF5: =IFERROR(SUM(W5,Y5,AA5,AC5,AE5),"") -> 0 | AH5: =IFERROR(IF(AG5="","",IF(AG5="Ischial",3,IF(AG5="Multiple Sites",1,0))),"") | AJ5: =IFERROR(IF(AI5="","",IF(AI5="<50 cm²",0,IF(AI5="50-100 cm²",1,2))),"") | AL5: =IFERROR(IF(AK5="","",IF(AK5="None",0,IF(AK5="Chronic (>4wk + sequestrum/sinus)",1,3))),"") | AN5: =IFERROR(IF(AM5="","",IF(AM5="None",0,IF(AM5="1 prior flap",2,3))),"") | AP5: =IFERROR(IF(AO5="","",IF(AO5="None",0,IF(AO5="Intermittent (not daily)",1,2))),"") | AR5: =IFERROR(IF(OR(AG5="Lower Extremity",AG5="Multiple Sites"),IF(AQ5="Y",1,0),0),"") -> 0 | AT5: =IFERROR(IF(AS5="Y",1,0),"") -> 0 | AU5: =IFERROR(SUM(AH5,AJ5,AL5,AN5,AP5,AR5,AT5),"") -> 0 | AW5: =IFERROR(IF(AV5="","",IF(AV5="No diabetes / HbA1c <7.0%",0,IF(AV5="HbA1c 7.0-7.9%",1,2))),"") | AY5: =IFERROR(IF(AX5="","",IF(AX5="Never / Former (>6mo abstinence)",0,2)),"") | BA5: =IFERROR(IF(AZ5="","",IF(AZ5="None",0,IF(AZ5="One stable condition",1,2))),"") | BC5: =IFERROR(IF(BB5="Y",2,0),"") -> 0 | BD5: =IFERROR(SUM(AW5,AY5,BA5,BC5),"") -> 0 | BF5: =IFERROR(IF(BE5="","",IF(BE5="Ambulatory",0,IF(BE5="Wheelchair w/ cushions",1,IF(BE5="Bedbound w/ offloading mattress",2,3)))),"") | BH5: =IFERROR(IF(BG5="","",IF(BG5="Reliable 24/7 care",0,IF(BG5="Some support — inconsistent",2,0))),"") | BI5: =IFERROR(SUM(BF5,BH5),"") -> 0 | BJ5: =IFERROR(IF(COUNTA(AF5,AU5,BD5,BI5)=0,"",SUM(AF5,AU5,BD5,BI5)),"") -> 0 | BK5: =IFERROR(IF(BJ5="","",IF(BJ5<6,"LOW RISK",IF(BJ5<13,"MODERATE RISK",IF(BJ5<20,"HIGH RISK","NOT AN IDEAL CANDIDATE")))),"") -> LOW RISK | BL5: =IFERROR(_xlfn.SINGLE(_xlfn.TEXTJOIN(", ", TRUE(), IF(V5 = "<2.5 g/dL (Abs CI)", "Albumin CI", ""), IF(AB5 = ">2.0 or Sepsis (Abs CI)", "PCT CI", ""), IF(BG5 = "No support (Functional CI)", "Functional CI", ""))), "") | BU5: =IFERROR(IF(BT5="","",IF(BT5<6,"LOW RISK",IF(BT5<13,"MODERATE RISK",IF(BT5<20,"HIGH RISK","NOT AN IDEAL CANDIDATE")))),"")
T6: =IF(COUNTIF(K6:S6,"Y")>0,"STOP — ABS CI PRESENT","✓ Clear to Score") -> ✓ Clear to Score | W6: =IFERROR(IF(V6="","",IF(V6="≥3.5 g/dL",0,IF(V6="3.0-3.49 g/dL",1,IF(V6="2.5-2.99 g/dL",3,0)))),"") | Y6: =IFERROR(IF(X6="","",IF(X6="≥18 mg/dL",0,IF(X6="12-17.9 mg/dL",1,2))),"") | AA6: =IFERROR(IF(Z6="","",IF(ISNUMBER(SEARCH("Normal",Z6)),0,IF(ISNUMBER(SEARCH("Borderline",Z6)),1,3))),"") | AC6: =IFERROR(IF(U6="N",0,IF(AB6="","",IF(AB6="0.5-2.0 ng/mL",1,0))),"") | AE6: =IFERROR(IF(U6="N",0,IF(AD6="Y",1,0)),"") -> 0 | AF6: =IFERROR(SUM(W6,Y6,AA6,AC6,AE6),"") -> 0 | AH6: =IFERROR(IF(AG6="","",IF(AG6="Ischial",3,IF(AG6="Multiple Sites",1,0))),"") | AJ6: =IFERROR(IF(AI6="","",IF(AI6="<50 cm²",0,IF(AI6="50-100 cm²",1,2))),"") | AL6: =IFERROR(IF(AK6="","",IF(AK6="None",0,IF(AK6="Chronic (>4wk + sequestrum/sinus)",1,3))),"") | AN6: =IFERROR(IF(AM6="","",IF(AM6="None",0,IF(AM6="1 prior flap",2,3))),"") | AP6: =IFERROR(IF(AO6="","",IF(AO6="None",0,IF(AO6="Intermittent (not daily)",1,2))),"") | AR6: =IFERROR(IF(OR(AG6="Lower Extremity",AG6="Multiple Sites"),IF(AQ6="Y",1,0),0),"") -> 0 | AT6: =IFERROR(IF(AS6="Y",1,0),"") -> 0 | AU6: =IFERROR(SUM(AH6,AJ6,AL6,AN6,AP6,AR6,AT6),"") -> 0 | AW6: =IFERROR(IF(AV6="","",IF(AV6="No diabetes / HbA1c <7.0%",0,IF(AV6="HbA1c 7.0-7.9%",1,2))),"") | AY6: =IFERROR(IF(AX6="","",IF(AX6="Never / Former (>6mo abstinence)",0,2)),"") | BA6: =IFERROR(IF(AZ6="","",IF(AZ6="None",0,IF(AZ6="One stable condition",1,2))),"") | BC6: =IFERROR(IF(BB6="Y",2,0),"") -> 0 | BD6: =IFERROR(SUM(AW6,AY6,BA6,BC6),"") -> 0 | BF6: =IFERROR(IF(BE6="","",IF(BE6="Ambulatory",0,IF(BE6="Wheelchair w/ cushions",1,IF(BE6="Bedbound w/ offloading mattress",2,3)))),"") | BH6: =IFERROR(IF(BG6="","",IF(BG6="Reliable 24/7 care",0,IF(BG6="Some support — inconsistent",2,0))),"") | BI6: =IFERROR(SUM(BF6,BH6),"") -> 0 | BJ6: =IFERROR(IF(COUNTA(AF6,AU6,BD6,BI6)=0,"",SUM(AF6,AU6,BD6,BI6)),"") -> 0 | BK6: =IFERROR(IF(BJ6="","",IF(BJ6<6,"LOW RISK",IF(BJ6<13,"MODERATE RISK",IF(BJ6<20,"HIGH RISK","NOT AN IDEAL CANDIDATE")))),"") -> LOW RISK | BL6: =IFERROR(_xlfn.SINGLE(_xlfn.TEXTJOIN(", ", TRUE(), IF(V6 = "<2.5 g/dL (Abs CI)", "Albumin CI", ""), IF(AB6 = ">2.0 or Sepsis (Abs CI)", "PCT CI", ""), IF(BG6 = "No support (Functional CI)", "Functional CI", ""))), "") | BU6: =IFERROR(IF(BT6="","",IF(BT6<6,"LOW RISK",IF(BT6<13,"MODERATE RISK",IF(BT6<20,"HIGH RISK","NOT AN IDEAL CANDIDATE")))),"")
T7: =IF(COUNTIF(K7:S7,"Y")>0,"STOP — ABS CI PRESENT","✓ Clear to Score") -> ✓ Clear to Score | W7: =IFERROR(IF(V7="","",IF(V7="≥3.5 g/dL",0,IF(V7="3.0-3.49 g/dL",1,IF(V7="2.5-2.99 g/dL",3,0)))),"") | Y7: =IFERROR(IF(X7="","",IF(X7="≥18 mg/dL",0,IF(X7="12-17.9 mg/dL",1,2))),"") | AA7: =IFERROR(IF(Z7="","",IF(ISNUMBER(SEARCH("Normal",Z7)),0,IF(ISNUMBER(SEARCH("Borderline",Z7)),1,3))),"") | AC7: =IFERROR(IF(U7="N",0,IF(AB7="","",IF(AB7="0.5-2.0 ng/mL",1,0))),"") | AE7: =IFERROR(IF(U7="N",0,IF(AD7="Y",1,0)),"") -> 0 | AF7: =IFERROR(SUM(W7,Y7,AA7,AC7,AE7),"") -> 0 | AH7: =IFERROR(IF(AG7="","",IF(AG7="Ischial",3,IF(AG7="Multiple Sites",1,0))),"") | AJ7: =IFERROR(IF(AI7="","",IF(AI7="<50 cm²",0,IF(AI7="50-100 cm²",1,2))),"") | AL7: =IFERROR(IF(AK7="","",IF(AK7="None",0,IF(AK7="Chronic (>4wk + sequestrum/sinus)",1,3))),"") | AN7: =IFERROR(IF(AM7="","",IF(AM7="None",0,IF(AM7="1 prior flap",2,3))),"") | AP7: =IFERROR(IF(AO7="","",IF(AO7="None",0,IF(AO7="Intermittent (not daily)",1,2))),"") | AR7: =IFERROR(IF(OR(AG7="Lower Extremity",AG7="Multiple Sites"),IF(AQ7="Y",1,0),0),"") -> 0 | AT7: =IFERROR(IF(AS7="Y",1,0),"") -> 0 | AU7: =IFERROR(SUM(AH7,AJ7,AL7,AN7,AP7,AR7,AT7),"") -> 0 | AW7: =IFERROR(IF(AV7="","",IF(AV7="No diabetes / HbA1c <7.0%",0,IF(AV7="HbA1c 7.0-7.9%",1,2))),"") | AY7: =IFERROR(IF(AX7="","",IF(AX7="Never / Former (>6mo abstinence)",0,2)),"") | BA7: =IFERROR(IF(AZ7="","",IF(AZ7="None",0,IF(AZ7="One stable condition",1,2))),"") | BC7: =IFERROR(IF(BB7="Y",2,0),"") -> 0 | BD7: =IFERROR(SUM(AW7,AY7,BA7,BC7),"") -> 0 | BF7: =IFERROR(IF(BE7="","",IF(BE7="Ambulatory",0,IF(BE7="Wheelchair w/ cushions",1,IF(BE7="Bedbound w/ offloading mattress",2,3)))),"") | BH7: =IFERROR(IF(BG7="","",IF(BG7="Reliable 24/7 care",0,IF(BG7="Some support — inconsistent",2,0))),"") | BI7: =IFERROR(SUM(BF7,BH7),"") -> 0 | BJ7: =IFERROR(IF(COUNTA(AF7,AU7,BD7,BI7)=0,"",SUM(AF7,AU7,BD7,BI7)),"") -> 0 | BK7: =IFERROR(IF(BJ7="","",IF(BJ7<6,"LOW RISK",IF(BJ7<13,"MODERATE RISK",IF(BJ7<20,"HIGH RISK","NOT AN IDEAL CANDIDATE")))),"") -> LOW RISK | BL7: =IFERROR(_xlfn.SINGLE(_xlfn.TEXTJOIN(", ", TRUE(), IF(V7 = "<2.5 g/dL (Abs CI)", "Albumin CI", ""), IF(AB7 = ">2.0 or Sepsis (Abs CI)", "PCT CI", ""), IF(BG7 = "No support (Functional CI)", "Functional CI", ""))), "") | BU7: =IFERROR(IF(BT7="","",IF(BT7<6,"LOW RISK",IF(BT7<13,"MODERATE RISK",IF(BT7<20,"HIGH RISK","NOT AN IDEAL CANDIDATE")))),"")
T8: =IF(COUNTIF(K8:S8,"Y")>0,"STOP — ABS CI PRESENT","✓ Clear to Score") -> ✓ Clear to Score | W8: =IFERROR(IF(V8="","",IF(V8="≥3.5 g/dL",0,IF(V8="3.0-3.49 g/dL",1,IF(V8="2.5-2.99 g/dL",3,0)))),"") | Y8: =IFERROR(IF(X8="","",IF(X8="≥18 mg/dL",0,IF(X8="12-17.9 mg/dL",1,2))),"") | AA8: =IFERROR(IF(Z8="","",IF(ISNUMBER(SEARCH("Normal",Z8)),0,IF(ISNUMBER(SEARCH("Borderline",Z8)),1,3))),"") | AC8: =IFERROR(IF(U8="N",0,IF(AB8="","",IF(AB8="0.5-2.0 ng/mL",1,0))),"") | AE8: =IFERROR(IF(U8="N",0,IF(AD8="Y",1,0)),"") -> 0 | AF8: =IFERROR(SUM(W8,Y8,AA8,AC8,AE8),"") -> 0 | AH8: =IFERROR(IF(AG8="","",IF(AG8="Ischial",3,IF(AG8="Multiple Sites",1,0))),"") | AJ8: =IFERROR(IF(AI8="","",IF(AI8="<50 cm²",0,IF(AI8="50-100 cm²",1,2))),"") | AL8: =IFERROR(IF(AK8="","",IF(AK8="None",0,IF(AK8="Chronic (>4wk + sequestrum/sinus)",1,3))),"") | AN8: =IFERROR(IF(AM8="","",IF(AM8="None",0,IF(AM8="1 prior flap",2,3))),"") | AP8: =IFERROR(IF(AO8="","",IF(AO8="None",0,IF(AO8="Intermittent (not daily)",1,2))),"") | AR8: =IFERROR(IF(OR(AG8="Lower Extremity",AG8="Multiple Sites"),IF(AQ8="Y",1,0),0),"") -> 0 | AT8: =IFERROR(IF(AS8="Y",1,0),"") -> 0 | AU8: =IFERROR(SUM(AH8,AJ8,AL8,AN8,AP8,AR8,AT8),"") -> 0 | AW8: =IFERROR(IF(AV8="","",IF(AV8="No diabetes / HbA1c <7.0%",0,IF(AV8="HbA1c 7.0-7.9%",1,2))),"") | AY8: =IFERROR(IF(AX8="","",IF(AX8="Never / Former (>6mo abstinence)",0,2)),"") | BA8: =IFERROR(IF(AZ8="","",IF(AZ8="None",0,IF(AZ8="One stable condition",1,2))),"") | BC8: =IFERROR(IF(BB8="Y",2,0),"") -> 0 | BD8: =IFERROR(SUM(AW8,AY8,BA8,BC8),"") -> 0 | BF8: =IFERROR(IF(BE8="","",IF(BE8="Ambulatory",0,IF(BE8="Wheelchair w/ cushions",1,IF(BE8="Bedbound w/ offloading mattress",2,3)))),"") | BH8: =IFERROR(IF(BG8="","",IF(BG8="Reliable 24/7 care",0,IF(BG8="Some support — inconsistent",2,0))),"") | BI8: =IFERROR(SUM(BF8,BH8),"") -> 0 | BJ8: =IFERROR(IF(COUNTA(AF8,AU8,BD8,BI8)=0,"",SUM(AF8,AU8,BD8,BI8)),"") -> 0 | BK8: =IFERROR(IF(BJ8="","",IF(BJ8<6,"LOW RISK",IF(BJ8<13,"MODERATE RISK",IF(BJ8<20,"HIGH RISK","NOT AN IDEAL CANDIDATE")))),"") -> LOW RISK | BL8: =IFERROR(_xlfn.SINGLE(_xlfn.TEXTJOIN(", ", TRUE(), IF(V8 = "<2.5 g/dL (Abs CI)", "Albumin CI", ""), IF(AB8 = ">2.0 or Sepsis (Abs CI)", "PCT CI", ""), IF(BG8 = "No support (Functional CI)", "Functional CI", ""))), "") | BU8: =IFERROR(IF(BT8="","",IF(BT8<6,"LOW RISK",IF(BT8<13,"MODERATE RISK",IF(BT8<20,"HIGH RISK","NOT AN IDEAL CANDIDATE")))),"")
T9: =IF(COUNTIF(K9:S9,"Y")>0,"STOP — ABS CI PRESENT","✓ Clear to Score") -> ✓ Clear to Score | W9: =IFERROR(IF(V9="","",IF(V9="≥3.5 g/dL",0,IF(V9="3.0-3.49 g/dL",1,IF(V9="2.5-2.99 g/dL",3,0)))),"") | Y9: =IFERROR(IF(X9="","",IF(X9="≥18 mg/dL",0,IF(X9="12-17.9 mg/dL",1,2))),"") | AA9: =IFERROR(IF(Z9="","",IF(ISNUMBER(SEARCH("Normal",Z9)),0,IF(ISNUMBER(SEARCH("Borderline",Z9)),1,3))),"") | AC9: =IFERROR(IF(U9="N",0,IF(AB9="","",IF(AB9="0.5-2.0 ng/mL",1,0))),"") | AE9: =IFERROR(IF(U9="N",0,IF(AD9="Y",1,0)),"") -> 0 | AF9: =IFERROR(SUM(W9,Y9,AA9,AC9,AE9),"") -> 0 | AH9: =IFERROR(IF(AG9="","",IF(AG9="Ischial",3,IF(AG9="Multiple Sites",1,0))),"") | AJ9: =IFERROR(IF(AI9="","",IF(AI9="<50 cm²",0,IF(AI9="50-100 cm²",1,2))),"") | AL9: =IFERROR(IF(AK9="","",IF(AK9="None",0,IF(AK9="Chronic (>4wk + sequestrum/sinus)",1,3))),"") | AN9: =IFERROR(IF(AM9="","",IF(AM9="None",0,IF(AM9="1 prior flap",2,3))),"") | AP9: =IFERROR(IF(AO9="","",IF(AO9="None",0,IF(AO9="Intermittent (not daily)",1,2))),"") | AR9: =IFERROR(IF(OR(AG9="Lower Extremity",AG9="Multiple Sites"),IF(AQ9="Y",1,0),0),"") -> 0 | AT9: =IFERROR(IF(AS9="Y",1,0),"") -> 0 | AU9: =IFERROR(SUM(AH9,AJ9,AL9,AN9,AP9,AR9,AT9),"") -> 0 | AW9: =IFERROR(IF(AV9="","",IF(AV9="No diabetes / HbA1c <7.0%",0,IF(AV9="HbA1c 7.0-7.9%",1,2))),"") | AY9: =IFERROR(IF(AX9="","",IF(AX9="Never / Former (>6mo abstinence)",0,2)),"") | BA9: =IFERROR(IF(AZ9="","",IF(AZ9="None",0,IF(AZ9="One stable condition",1,2))),"") | BC9: =IFERROR(IF(BB9="Y",2,0),"") -> 0 | BD9: =IFERROR(SUM(AW9,AY9,BA9,BC9),"") -> 0 | BF9: =IFERROR(IF(BE9="","",IF(BE9="Ambulatory",0,IF(BE9="Wheelchair w/ cushions",1,IF(BE9="Bedbound w/ offloading mattress",2,3)))),"") | BH9: =IFERROR(IF(BG9="","",IF(BG9="Reliable 24/7 care",0,IF(BG9="Some support — inconsistent",2,0))),"") | BI9: =IFERROR(SUM(BF9,BH9),"") -> 0 | BJ9: =IFERROR(IF(COUNTA(AF9,AU9,BD9,BI9)=0,"",SUM(AF9,AU9,BD9,BI9)),"") -> 0 | BK9: =IFERROR(IF(BJ9="","",IF(BJ9<6,"LOW RISK",IF(BJ9<13,"MODERATE RISK",IF(BJ9<20,"HIGH RISK","NOT AN IDEAL CANDIDATE")))),"") -> LOW RISK | BL9: =IFERROR(_xlfn.SINGLE(_xlfn.TEXTJOIN(", ", TRUE(), IF(V9 = "<2.5 g/dL (Abs CI)", "Albumin CI", ""), IF(AB9 = ">2.0 or Sepsis (Abs CI)", "PCT CI", ""), IF(BG9 = "No support (Functional CI)", "Functional CI", ""))), "") | BU9: =IFERROR(IF(BT9="","",IF(BT9<6,"LOW RISK",IF(BT9<13,"MODERATE RISK",IF(BT9<20,"HIGH RISK","NOT AN IDEAL CANDIDATE")))),"")
T10: =IF(COUNTIF(K10:S10,"Y")>0,"STOP — ABS CI PRESENT","✓ Clear to Score") -> ✓ Clear to Score | W10: =IFERROR(IF(V10="","",IF(V10="≥3.5 g/dL",0,IF(V10="3.0-3.49 g/dL",1,IF(V10="2.5-2.99 g/dL",3,0)))),"") | Y10: =IFERROR(IF(X10="","",IF(X10="≥18 mg/dL",0,IF(X10="12-17.9 mg/dL",1,2))),"") | AA10: =IFERROR(IF(Z10="","",IF(ISNUMBER(SEARCH("Normal",Z10)),0,IF(ISNUMBER(SEARCH("Borderline",Z10)),1,3))),"") | AC10: =IFERROR(IF(U10="N",0,IF(AB10="","",IF(AB10="0.5-2.0 ng/mL",1,0))),"") | AE10: =IFERROR(IF(U10="N",0,IF(AD10="Y",1,0)),"") -> 0 | AF10: =IFERROR(SUM(W10,Y10,AA10,AC10,AE10),"") -> 0 | AH10: =IFERROR(IF(AG10="","",IF(AG10="Ischial",3,IF(AG10="Multiple Sites",1,0))),"") | AJ10: =IFERROR(IF(AI10="","",IF(AI10="<50 cm²",0,IF(AI10="50-100 cm²",1,2))),"") | AL10: =IFERROR(IF(AK10="","",IF(AK10="None",0,IF(AK10="Chronic (>4wk + sequestrum/sinus)",1,3))),"") | AN10: =IFERROR(IF(AM10="","",IF(AM10="None",0,IF(AM10="1 prior flap",2,3))),"") | AP10: =IFERROR(IF(AO10="","",IF(AO10="None",0,IF(AO10="Intermittent (not daily)",1,2))),"") | AR10: =IFERROR(IF(OR(AG10="Lower Extremity",AG10="Multiple Sites"),IF(AQ10="Y",1,0),0),"") -> 0 | AT10: =IFERROR(IF(AS10="Y",1,0),"") -> 0 | AU10: =IFERROR(SUM(AH10,AJ10,AL10,AN10,AP10,AR10,AT10),"") -> 0 | AW10: =IFERROR(IF(AV10="","",IF(AV10="No diabetes / HbA1c <7.0%",0,IF(AV10="HbA1c 7.0-7.9%",1,2))),"") | AY10: =IFERROR(IF(AX10="","",IF(AX10="Never / Former (>6mo abstinence)",0,2)),"") | BA10: =IFERROR(IF(AZ10="","",IF(AZ10="None",0,IF(AZ10="One stable condition",1,2))),"") | BC10: =IFERROR(IF(BB10="Y",2,0),"") -> 0 | BD10: =IFERROR(SUM(AW10,AY10,BA10,BC10),"") -> 0 | BF10: =IFERROR(IF(BE10="","",IF(BE10="Ambulatory",0,IF(BE10="Wheelchair w/ cushions",1,IF(BE10="Bedbound w/ offloading mattress",2,3)))),"") | BH10: =IFERROR(IF(BG10="","",IF(BG10="Reliable 24/7 care",0,IF(BG10="Some support — inconsistent",2,0))),"") | BI10: =IFERROR(SUM(BF10,BH10),"") -> 0 | BJ10: =IFERROR(IF(COUNTA(AF10,AU10,BD10,BI10)=0,"",SUM(AF10,AU10,BD10,BI10)),"") -> 0 | BK10: =IFERROR(IF(BJ10="","",IF(BJ10<6,"LOW RISK",IF(BJ10<13,"MODERATE RISK",IF(BJ10<20,"HIGH RISK","NOT AN IDEAL CANDIDATE")))),"") -> LOW RISK | BL10: =IFERROR(_xlfn.SINGLE(_xlfn.TEXTJOIN(", ", TRUE(), IF(V10 = "<2.5 g/dL (Abs CI)", "Albumin CI", ""), IF(AB10 = ">2.0 or Sepsis (Abs CI)", "PCT CI", ""), IF(BG10 = "No support (Functional CI)", "Functional CI", ""))), "") | BU10: =IFERROR(IF(BT10="","",IF(BT10<6,"LOW RISK",IF(BT10<13,"MODERATE RISK",IF(BT10<20,"HIGH RISK","NOT AN IDEAL CANDIDATE")))),"")
T11: =IF(COUNTIF(K11:S11,"Y")>0,"STOP — ABS CI PRESENT","✓ Clear to Score") -> ✓ Clear to Score | W11: =IFERROR(IF(V11="","",IF(V11="≥3.5 g/dL",0,IF(V11="3.0-3.49 g/dL",1,IF(V11="2.5-2.99 g/dL",3,0)))),"") | Y11: =IFERROR(IF(X11="","",IF(X11="≥18 mg/dL",0,IF(X11="12-17.9 mg/dL",1,2))),"") | AA11: =IFERROR(IF(Z11="","",IF(ISNUMBER(SEARCH("Normal",Z11)),0,IF(ISNUMBER(SEARCH("Borderline",Z11)),1,3))),"") | AC11: =IFERROR(IF(U11="N",0,IF(AB11="","",IF(AB11="0.5-2.0 ng/mL",1,0))),"") | AE11: =IFERROR(IF(U11="N",0,IF(AD11="Y",1,0)),"") -> 0 | AF11: =IFERROR(SUM(W11,Y11,AA11,AC11,AE11),"") -> 0 | AH11: =IFERROR(IF(AG11="","",IF(AG11="Ischial",3,IF(AG11="Multiple Sites",1,0))),"") | AJ11: =IFERROR(IF(AI11="","",IF(AI11="<50 cm²",0,IF(AI11="50-100 cm²",1,2))),"") | AL11: =IFERROR(IF(AK11="","",IF(AK11="None",0,IF(AK11="Chronic (>4wk + sequestrum/sinus)",1,3))),"") | AN11: =IFERROR(IF(AM11="","",IF(AM11="None",0,IF(AM11="1 prior flap",2,3))),"") | AP11: =IFERROR(IF(AO11="","",IF(AO11="None",0,IF(AO11="Intermittent (not daily)",1,2))),"") | AR11: =IFERROR(IF(OR(AG11="Lower Extremity",AG11="Multiple Sites"),IF(AQ11="Y",1,0),0),"") -> 0 | AT11: =IFERROR(IF(AS11="Y",1,0),"") -> 0 | AU11: =IFERROR(SUM(AH11,AJ11,AL11,AN11,AP11,AR11,AT11),"") -> 0 | AW11: =IFERROR(IF(AV11="","",IF(AV11="No diabetes / HbA1c <7.0%",0,IF(AV11="HbA1c 7.0-7.9%",1,2))),"") | AY11: =IFERROR(IF(AX11="","",IF(AX11="Never / Former (>6mo abstinence)",0,2)),"") | BA11: =IFERROR(IF(AZ11="","",IF(AZ11="None",0,IF(AZ11="One stable condition",1,2))),"") | BC11: =IFERROR(IF(BB11="Y",2,0),"") -> 0 | BD11: =IFERROR(SUM(AW11,AY11,BA11,BC11),"") -> 0 | BF11: =IFERROR(IF(BE11="","",IF(BE11="Ambulatory",0,IF(BE11="Wheelchair w/ cushions",1,IF(BE11="Bedbound w/ offloading mattress",2,3)))),"") | BH11: =IFERROR(IF(BG11="","",IF(BG11="Reliable 24/7 care",0,IF(BG11="Some support — inconsistent",2,0))),"") | BI11: =IFERROR(SUM(BF11,BH11),"") -> 0 | BJ11: =IFERROR(IF(COUNTA(AF11,AU11,BD11,BI11)=0,"",SUM(AF11,AU11,BD11,BI11)),"") -> 0 | BK11: =IFERROR(IF(BJ11="","",IF(BJ11<6,"LOW RISK",IF(BJ11<13,"MODERATE RISK",IF(BJ11<20,"HIGH RISK","NOT AN IDEAL CANDIDATE")))),"") -> LOW RISK | BL11: =IFERROR(_xlfn.SINGLE(_xlfn.TEXTJOIN(", ", TRUE(), IF(V11 = "<2.5 g/dL (Abs CI)", "Albumin CI", ""), IF(AB11 = ">2.0 or Sepsis (Abs CI)", "PCT CI", ""), IF(BG11 = "No support (Functional CI)", "Functional CI", ""))), "") | BU11: =IFERROR(IF(BT11="","",IF(BT11<6,"LOW RISK",IF(BT11<13,"MODERATE RISK",IF(BT11<20,"HIGH RISK","NOT AN IDEAL CANDIDATE")))),"") | CC11: =IFERROR(IF(COUNTA(BV11:CB11)=0,"",IF(COUNTIF(BV11:CB11,"Y")>0,"YES — EVENT","NO event")),"")
T12: =IF(COUNTIF(K12:S12,"Y")>0,"STOP — ABS CI PRESENT","✓ Clear to Score") -> ✓ Clear to Score | W12: =IFERROR(IF(V12="","",IF(V12="≥3.5 g/dL",0,IF(V12="3.0-3.49 g/dL",1,IF(V12="2.5-2.99 g/dL",3,0)))),"") | Y12: =IFERROR(IF(X12="","",IF(X12="≥18 mg/dL",0,IF(X12="12-17.9 mg/dL",1,2))),"") | AA12: =IFERROR(IF(Z12="","",IF(ISNUMBER(SEARCH("Normal",Z12)),0,IF(ISNUMBER(SEARCH("Borderline",Z12)),1,3))),"") | AC12: =IFERROR(IF(U12="N",0,IF(AB12="","",IF(AB12="0.5-2.0 ng/mL",1,0))),"") | AE12: =IFERROR(IF(U12="N",0,IF(AD12="Y",1,0)),"") -> 0 | AF12: =IFERROR(SUM(W12,Y12,AA12,AC12,AE12),"") -> 0 | AH12: =IFERROR(IF(AG12="","",IF(AG12="Ischial",3,IF(AG12="Multiple Sites",1,0))),"") | AJ12: =IFERROR(IF(AI12="","",IF(AI12="<50 cm²",0,IF(AI12="50-100 cm²",1,2))),"") | AL12: =IFERROR(IF(AK12="","",IF(AK12="None",0,IF(AK12="Chronic (>4wk + sequestrum/sinus)",1,3))),"") | AN12: =IFERROR(IF(AM12="","",IF(AM12="None",0,IF(AM12="1 prior flap",2,3))),"") | AP12: =IFERROR(IF(AO12="","",IF(AO12="None",0,IF(AO12="Intermittent (not daily)",1,2))),"") | AR12: =IFERROR(IF(OR(AG12="Lower Extremity",AG12="Multiple Sites"),IF(AQ12="Y",1,0),0),"") -> 0 | AT12: =IFERROR(IF(AS12="Y",1,0),"") -> 0 | AU12: =IFERROR(SUM(AH12,AJ12,AL12,AN12,AP12,AR12,AT12),"") -> 0 | AW12: =IFERROR(IF(AV12="","",IF(AV12="No diabetes / HbA1c <7.0%",0,IF(AV12="HbA1c 7.0-7.9%",1,2))),"") | AY12: =IFERROR(IF(AX12="","",IF(AX12="Never / Former (>6mo abstinence)",0,2)),"") | BA12: =IFERROR(IF(AZ12="","",IF(AZ12="None",0,IF(AZ12="One stable condition",1,2))),"") | BC12: =IFERROR(IF(BB12="Y",2,0),"") -> 0 | BD12: =IFERROR(SUM(AW12,AY12,BA12,BC12),"") -> 0 | BF12: =IFERROR(IF(BE12="","",IF(BE12="Ambulatory",0,IF(BE12="Wheelchair w/ cushions",1,IF(BE12="Bedbound w/ offloading mattress",2,3)))),"") | BH12: =IFERROR(IF(BG12="","",IF(BG12="Reliable 24/7 care",0,IF(BG12="Some support — inconsistent",2,0))),"") | BI12: =IFERROR(SUM(BF12,BH12),"") -> 0 | BJ12: =IFERROR(IF(COUNTA(AF12,AU12,BD12,BI12)=0,"",SUM(AF12,AU12,BD12,BI12)),"") -> 0 | BK12: =IFERROR(IF(BJ12="","",IF(BJ12<6,"LOW RISK",IF(BJ12<13,"MODERATE RISK",IF(BJ12<20,"HIGH RISK","NOT AN IDEAL CANDIDATE")))),"") -> LOW RISK | BL12: =IFERROR(_xlfn.SINGLE(_xlfn.TEXTJOIN(", ", TRUE(), IF(V12 = "<2.5 g/dL (Abs CI)", "Albumin CI", ""), IF(AB12 = ">2.0 or Sepsis (Abs CI)", "PCT CI", ""), IF(BG12 = "No support (Functional CI)", "Functional CI", ""))), "") | BU12: =IFERROR(IF(BT12="","",IF(BT12<6,"LOW RISK",IF(BT12<13,"MODERATE RISK",IF(BT12<20,"HIGH RISK","NOT AN IDEAL CANDIDATE")))),"") | CC12: =IFERROR(IF(COUNTA(BV12:CB12)=0,"",IF(COUNTIF(BV12:CB12,"Y")>0,"YES — EVENT","NO event")),"")
T13: =IF(COUNTIF(K13:S13,"Y")>0,"STOP — ABS CI PRESENT","✓ Clear to Score") -> ✓ Clear to Score | W13: =IFERROR(IF(V13="","",IF(V13="≥3.5 g/dL",0,IF(V13="3.0-3.49 g/dL",1,IF(V13="2.5-2.99 g/dL",3,0)))),"") | Y13: =IFERROR(IF(X13="","",IF(X13="≥18 mg/dL",0,IF(X13="12-17.9 mg/dL",1,2))),"") | AA13: =IFERROR(IF(Z13="","",IF(ISNUMBER(SEARCH("Normal",Z13)),0,IF(ISNUMBER(SEARCH("Borderline",Z13)),1,3))),"") | AC13: =IFERROR(IF(U13="N",0,IF(AB13="","",IF(AB13="0.5-2.0 ng/mL",1,0))),"") | AE13: =IFERROR(IF(U13="N",0,IF(AD13="Y",1,0)),"") -> 0 | AF13: =IFERROR(SUM(W13,Y13,AA13,AC13,AE13),"") -> 0 | AH13: =IFERROR(IF(AG13="","",IF(AG13="Ischial",3,IF(AG13="Multiple Sites",1,0))),"") | AJ13: =IFERROR(IF(AI13="","",IF(AI13="<50 cm²",0,IF(AI13="50-100 cm²",1,2))),"") | AL13: =IFERROR(IF(AK13="","",IF(AK13="None",0,IF(AK13="Chronic (>4wk + sequestrum/sinus)",1,3))),"") | AN13: =IFERROR(IF(AM13="","",IF(AM13="None",0,IF(AM13="1 prior flap",2,3))),"") | AP13: =IFERROR(IF(AO13="","",IF(AO13="None",0,IF(AO13="Intermittent (not daily)",1,2))),"") | AR13: =IFERROR(IF(OR(AG13="Lower Extremity",AG13="Multiple Sites"),IF(AQ13="Y",1,0),0),"") -> 0 | AT13: =IFERROR(IF(AS13="Y",1,0),"") -> 0 | AU13: =IFERROR(SUM(AH13,AJ13,AL13,AN13,AP13,AR13,AT13),"") -> 0 | AW13: =IFERROR(IF(AV13="","",IF(AV13="No diabetes / HbA1c <7.0%",0,IF(AV13="HbA1c 7.0-7.9%",1,2))),"") | AY13: =IFERROR(IF(AX13="","",IF(AX13="Never / Former (>6mo abstinence)",0,2)),"") | BA13: =IFERROR(IF(AZ13="","",IF(AZ13="None",0,IF(AZ13="One stable condition",1,2))),"") | BC13: =IFERROR(IF(BB13="Y",2,0),"") -> 0 | BD13: =IFERROR(SUM(AW13,AY13,BA13,BC13),"") -> 0 | BF13: =IFERROR(IF(BE13="","",IF(BE13="Ambulatory",0,IF(BE13="Wheelchair w/ cushions",1,IF(BE13="Bedbound w/ offloading mattress",2,3)))),"") | BH13: =IFERROR(IF(BG13="","",IF(BG13="Reliable 24/7 care",0,IF(BG13="Some support — inconsistent",2,0))),"") | BI13: =IFERROR(SUM(BF13,BH13),"") -> 0 | BJ13: =IFERROR(IF(COUNTA(AF13,AU13,BD13,BI13)=0,"",SUM(AF13,AU13,BD13,BI13)),"") -> 0 | BK13: =IFERROR(IF(BJ13="","",IF(BJ13<6,"LOW RISK",IF(BJ13<13,"MODERATE RISK",IF(BJ13<20,"HIGH RISK","NOT AN IDEAL CANDIDATE")))),"") -> LOW RISK | BL13: =IFERROR(_xlfn.SINGLE(_xlfn.TEXTJOIN(", ", TRUE(), IF(V13 = "<2.5 g/dL (Abs CI)", "Albumin CI", ""), IF(AB13 = ">2.0 or Sepsis (Abs CI)", "PCT CI", ""), IF(BG13 = "No support (Functional CI)", "Functional CI", ""))), "") | BU13: =IFERROR(IF(BT13="","",IF(BT13<6,"LOW RISK",IF(BT13<13,"MODERATE RISK",IF(BT13<20,"HIGH RISK","NOT AN IDEAL CANDIDATE")))),"") | CC13: =IFERROR(IF(COUNTA(BV13:CB13)=0,"",IF(COUNTIF(BV13:CB13,"Y")>0,"YES — EVENT","NO event")),"")
T14: =IF(COUNTIF(K14:S14,"Y")>0,"STOP — ABS CI PRESENT","✓ Clear to Score") -> ✓ Clear to Score | W14: =IFERROR(IF(V14="","",IF(V14="≥3.5 g/dL",0,IF(V14="3.0-3.49 g/dL",1,IF(V14="2.5-2.99 g/dL",3,0)))),"") | Y14: =IFERROR(IF(X14="","",IF(X14="≥18 mg/dL",0,IF(X14="12-17.9 mg/dL",1,2))),"") | AA14: =IFERROR(IF(Z14="","",IF(ISNUMBER(SEARCH("Normal",Z14)),0,IF(ISNUMBER(SEARCH("Borderline",Z14)),1,3))),"") | AC14: =IFERROR(IF(U14="N",0,IF(AB14="","",IF(AB14="0.5-2.0 ng/mL",1,0))),"") | AE14: =IFERROR(IF(U14="N",0,IF(AD14="Y",1,0)),"") -> 0 | AF14: =IFERROR(SUM(W14,Y14,AA14,AC14,AE14),"") -> 0 | AH14: =IFERROR(IF(AG14="","",IF(AG14="Ischial",3,IF(AG14="Multiple Sites",1,0))),"") | AJ14: =IFERROR(IF(AI14="","",IF(AI14="<50 cm²",0,IF(AI14="50-100 cm²",1,2))),"") | AL14: =IFERROR(IF(AK14="","",IF(AK14="None",0,IF(AK14="Chronic (>4wk + sequestrum/sinus)",1,3))),"") | AN14: =IFERROR(IF(AM14="","",IF(AM14="None",0,IF(AM14="1 prior flap",2,3))),"") | AP14: =IFERROR(IF(AO14="","",IF(AO14="None",0,IF(AO14="Intermittent (not daily)",1,2))),"") | AR14: =IFERROR(IF(OR(AG14="Lower Extremity",AG14="Multiple Sites"),IF(AQ14="Y",1,0),0),"") -> 0 | AT14: =IFERROR(IF(AS14="Y",1,0),"") -> 0 | AU14: =IFERROR(SUM(AH14,AJ14,AL14,AN14,AP14,AR14,AT14),"") -> 0 | AW14: =IFERROR(IF(AV14="","",IF(AV14="No diabetes / HbA1c <7.0%",0,IF(AV14="HbA1c 7.0-7.9%",1,2))),"") | AY14: =IFERROR(IF(AX14="","",IF(AX14="Never / Former (>6mo abstinence)",0,2)),"") | BA14: =IFERROR(IF(AZ14="","",IF(AZ14="None",0,IF(AZ14="One stable condition",1,2))),"") | BC14: =IFERROR(IF(BB14="Y",2,0),"") -> 0 | BD14: =IFERROR(SUM(AW14,AY14,BA14,BC14),"") -> 0 | BF14: =IFERROR(IF(BE14="","",IF(BE14="Ambulatory",0,IF(BE14="Wheelchair w/ cushions",1,IF(BE14="Bedbound w/ offloading mattress",2,3)))),"") | BH14: =IFERROR(IF(BG14="","",IF(BG14="Reliable 24/7 care",0,IF(BG14="Some support — inconsistent",2,0))),"") | BI14: =IFERROR(SUM(BF14,BH14),"") -> 0 | BJ14: =IFERROR(IF(COUNTA(AF14,AU14,BD14,BI14)=0,"",SUM(AF14,AU14,BD14,BI14)),"") -> 0 | BK14: =IFERROR(IF(BJ14="","",IF(BJ14<6,"LOW RISK",IF(BJ14<13,"MODERATE RISK",IF(BJ14<20,"HIGH RISK","NOT AN IDEAL CANDIDATE")))),"") -> LOW RISK | BL14: =IFERROR(_xlfn.SINGLE(_xlfn.TEXTJOIN(", ", TRUE(), IF(V14 = "<2.5 g/dL (Abs CI)", "Albumin CI", ""), IF(AB14 = ">2.0 or Sepsis (Abs CI)", "PCT CI", ""), IF(BG14 = "No support (Functional CI)", "Functional CI", ""))), "") | BU14: =IFERROR(IF(BT14="","",IF(BT14<6,"LOW RISK",IF(BT14<13,"MODERATE RISK",IF(BT14<20,"HIGH RISK","NOT AN IDEAL CANDIDATE")))),"") | CC14: =IFERROR(IF(COUNTA(BV14:CB14)=0,"",IF(COUNTIF(BV14:CB14,"Y")>0,"YES — EVENT","NO event")),"")
T15: =IF(COUNTIF(K15:S15,"Y")>0,"STOP — ABS CI PRESENT","✓ Clear to Score") -> ✓ Clear to Score | W15: =IFERROR(IF(V15="","",IF(V15="≥3.5 g/dL",0,IF(V15="3.0-3.49 g/dL",1,IF(V15="2.5-2.99 g/dL",3,0)))),"") | Y15: =IFERROR(IF(X15="","",IF(X15="≥18 mg/dL",0,IF(X15="12-17.9 mg/dL",1,2))),"") | AA15: =IFERROR(IF(Z15="","",IF(ISNUMBER(SEARCH("Normal",Z15)),0,IF(ISNUMBER(SEARCH("Borderline",Z15)),1,3))),"") | AC15: =IFERROR(IF(U15="N",0,IF(AB15="","",IF(AB15="0.5-2.0 ng/mL",1,0))),"") | AE15: =IFERROR(IF(U15="N",0,IF(AD15="Y",1,0)),"") -> 0 | AF15: =IFERROR(SUM(W15,Y15,AA15,AC15,AE15),"") -> 0 | AH15: =IFERROR(IF(AG15="","",IF(AG15="Ischial",3,IF(AG15="Multiple Sites",1,0))),"") | AJ15: =IFERROR(IF(AI15="","",IF(AI15="<50 cm²",0,IF(AI15="50-100 cm²",1,2))),"") | AL15: =IFERROR(IF(AK15="","",IF(AK15="None",0,IF(AK15="Chronic (>4wk + sequestrum/sinus)",1,3))),"") | AN15: =IFERROR(IF(AM15="","",IF(AM15="None",0,IF(AM15="1 prior flap",2,3))),"") | AP15: =IFERROR(IF(AO15="","",IF(AO15="None",0,IF(AO15="Intermittent (not daily)",1,2))),"") | AR15: =IFERROR(IF(OR(AG15="Lower Extremity",AG15="Multiple Sites"),IF(AQ15="Y",1,0),0),"") -> 0 | AT15: =IFERROR(IF(AS15="Y",1,0),"") -> 0 | AU15: =IFERROR(SUM(AH15,AJ15,AL15,AN15,AP15,AR15,AT15),"") -> 0 | AW15: =IFERROR(IF(AV15="","",IF(AV15="No diabetes / HbA1c <7.0%",0,IF(AV15="HbA1c 7.0-7.9%",1,2))),"") | AY15: =IFERROR(IF(AX15="","",IF(AX15="Never / Former (>6mo abstinence)",0,2)),"") | BA15: =IFERROR(IF(AZ15="","",IF(AZ15="None",0,IF(AZ15="One stable condition",1,2))),"") | BC15: =IFERROR(IF(BB15="Y",2,0),"") -> 0 | BD15: =IFERROR(SUM(AW15,AY15,BA15,BC15),"") -> 0 | BF15: =IFERROR(IF(BE15="","",IF(BE15="Ambulatory",0,IF(BE15="Wheelchair w/ cushions",1,IF(BE15="Bedbound w/ offloading mattress",2,3)))),"") | BH15: =IFERROR(IF(BG15="","",IF(BG15="Reliable 24/7 care",0,IF(BG15="Some support — inconsistent",2,0))),"") | BI15: =IFERROR(SUM(BF15,BH15),"") -> 0 | BJ15: =IFERROR(IF(COUNTA(AF15,AU15,BD15,BI15)=0,"",SUM(AF15,AU15,BD15,BI15)),"") -> 0 | BK15: =IFERROR(IF(BJ15="","",IF(BJ15<6,"LOW RISK",IF(BJ15<13,"MODERATE RISK",IF(BJ15<20,"HIGH RISK","NOT AN IDEAL CANDIDATE")))),"") -> LOW RISK | BL15: =IFERROR(_xlfn.SINGLE(_xlfn.TEXTJOIN(", ", TRUE(), IF(V15 = "<2.5 g/dL (Abs CI)", "Albumin CI", ""), IF(AB15 = ">2.0 or Sepsis (Abs CI)", "PCT CI", ""), IF(BG15 = "No support (Functional CI)", "Functional CI", ""))), "") | BU15: =IFERROR(IF(BT15="","",IF(BT15<6,"LOW RISK",IF(BT15<13,"MODERATE RISK",IF(BT15<20,"HIGH RISK","NOT AN IDEAL CANDIDATE")))),"") | CC15: =IFERROR(IF(COUNTA(BV15:CB15)=0,"",IF(COUNTIF(BV15:CB15,"Y")>0,"YES — EVENT","NO event")),"")
T16: =IF(COUNTIF(K16:S16,"Y")>0,"STOP — ABS CI PRESENT","✓ Clear to Score") -> ✓ Clear to Score | W16: =IFERROR(IF(V16="","",IF(V16="≥3.5 g/dL",0,IF(V16="3.0-3.49 g/dL",1,IF(V16="2.5-2.99 g/dL",3,0)))),"") | Y16: =IFERROR(IF(X16="","",IF(X16="≥18 mg/dL",0,IF(X16="12-17.9 mg/dL",1,2))),"") | AA16: =IFERROR(IF(Z16="","",IF(ISNUMBER(SEARCH("Normal",Z16)),0,IF(ISNUMBER(SEARCH("Borderline",Z16)),1,3))),"") | AC16: =IFERROR(IF(U16="N",0,IF(AB16="","",IF(AB16="0.5-2.0 ng/mL",1,0))),"") | AE16: =IFERROR(IF(U16="N",0,IF(AD16="Y",1,0)),"") -> 0 | AF16: =IFERROR(SUM(W16,Y16,AA16,AC16,AE16),"") -> 0 | AH16: =IFERROR(IF(AG16="","",IF(AG16="Ischial",3,IF(AG16="Multiple Sites",1,0))),"") | AJ16: =IFERROR(IF(AI16="","",IF(AI16="<50 cm²",0,IF(AI16="50-100 cm²",1,2))),"") | AL16: =IFERROR(IF(AK16="","",IF(AK16="None",0,IF(AK16="Chronic (>4wk + sequestrum/sinus)",1,3))),"") | AN16: =IFERROR(IF(AM16="","",IF(AM16="None",0,IF(AM16="1 prior flap",2,3))),"") | AP16: =IFERROR(IF(AO16="","",IF(AO16="None",0,IF(AO16="Intermittent (not daily)",1,2))),"") | AR16: =IFERROR(IF(OR(AG16="Lower Extremity",AG16="Multiple Sites"),IF(AQ16="Y",1,0),0),"") -> 0 | AT16: =IFERROR(IF(AS16="Y",1,0),"") -> 0 | AU16: =IFERROR(SUM(AH16,AJ16,AL16,AN16,AP16,AR16,AT16),"") -> 0 | AW16: =IFERROR(IF(AV16="","",IF(AV16="No diabetes / HbA1c <7.0%",0,IF(AV16="HbA1c 7.0-7.9%",1,2))),"") | AY16: =IFERROR(IF(AX16="","",IF(AX16="Never / Former (>6mo abstinence)",0,2)),"") | BA16: =IFERROR(IF(AZ16="","",IF(AZ16="None",0,IF(AZ16="One stable condition",1,2))),"") | BC16: =IFERROR(IF(BB16="Y",2,0),"") -> 0 | BD16: =IFERROR(SUM(AW16,AY16,BA16,BC16),"") -> 0 | BF16: =IFERROR(IF(BE16="","",IF(BE16="Ambulatory",0,IF(BE16="Wheelchair w/ cushions",1,IF(BE16="Bedbound w/ offloading mattress",2,3)))),"") | BH16: =IFERROR(IF(BG16="","",IF(BG16="Reliable 24/7 care",0,IF(BG16="Some support — inconsistent",2,0))),"") | BI16: =IFERROR(SUM(BF16,BH16),"") -> 0 | BJ16: =IFERROR(IF(COUNTA(AF16,AU16,BD16,BI16)=0,"",SUM(AF16,AU16,BD16,BI16)),"") -> 0 | BK16: =IFERROR(IF(BJ16="","",IF(BJ16<6,"LOW RISK",IF(BJ16<13,"MODERATE RISK",IF(BJ16<20,"HIGH RISK","NOT AN IDEAL CANDIDATE")))),"") -> LOW RISK | BL16: =IFERROR(_xlfn.SINGLE(_xlfn.TEXTJOIN(", ", TRUE(), IF(V16 = "<2.5 g/dL (Abs CI)", "Albumin CI", ""), IF(AB16 = ">2.0 or Sepsis (Abs CI)", "PCT CI", ""), IF(BG16 = "No support (Functional CI)", "Functional CI", ""))), "") | BU16: =IFERROR(IF(BT16="","",IF(BT16<6,"LOW RISK",IF(BT16<13,"MODERATE RISK",IF(BT16<20,"HIGH RISK","NOT AN IDEAL CANDIDATE")))),"") | CC16: =IFERROR(IF(COUNTA(BV16:CB16)=0,"",IF(COUNTIF(BV16:CB16,"Y")>0,"YES — EVENT","NO event")),"")
T17: =IF(COUNTIF(K17:S17,"Y")>0,"STOP — ABS CI PRESENT","✓ Clear to Score") -> ✓ Clear to Score | W17: =IFERROR(IF(V17="","",IF(V17="≥3.5 g/dL",0,IF(V17="3.0-3.49 g/dL",1,IF(V17="2.5-2.99 g/dL",3,0)))),"") | Y17: =IFERROR(IF(X17="","",IF(X17="≥18 mg/dL",0,IF(X17="12-17.9 mg/dL",1,2))),"") | AA17: =IFERROR(IF(Z17="","",IF(ISNUMBER(SEARCH("Normal",Z17)),0,IF(ISNUMBER(SEARCH("Borderline",Z17)),1,3))),"") | AC17: =IFERROR(IF(U17="N",0,IF(AB17="","",IF(AB17="0.5-2.0 ng/mL",1,0))),"") | AE17: =IFERROR(IF(U17="N",0,IF(AD17="Y",1,0)),"") -> 0 | AF17: =IFERROR(SUM(W17,Y17,AA17,AC17,AE17),"") -> 0 | AH17: =IFERROR(IF(AG17="","",IF(AG17="Ischial",3,IF(AG17="Multiple Sites",1,0))),"") | AJ17: =IFERROR(IF(AI17="","",IF(AI17="<50 cm²",0,IF(AI17="50-100 cm²",1,2))),"") | AL17: =IFERROR(IF(AK17="","",IF(AK17="None",0,IF(AK17="Chronic (>4wk + sequestrum/sinus)",1,3))),"") | AN17: =IFERROR(IF(AM17="","",IF(AM17="None",0,IF(AM17="1 prior flap",2,3))),"") | AP17: =IFERROR(IF(AO17="","",IF(AO17="None",0,IF(AO17="Intermittent (not daily)",1,2))),"") | AR17: =IFERROR(IF(OR(AG17="Lower Extremity",AG17="Multiple Sites"),IF(AQ17="Y",1,0),0),"") -> 0 | AT17: =IFERROR(IF(AS17="Y",1,0),"") -> 0 | AU17: =IFERROR(SUM(AH17,AJ17,AL17,AN17,AP17,AR17,AT17),"") -> 0 | AW17: =IFERROR(IF(AV17="","",IF(AV17="No diabetes / HbA1c <7.0%",0,IF(AV17="HbA1c 7.0-7.9%",1,2))),"") | AY17: =IFERROR(IF(AX17="","",IF(AX17="Never / Former (>6mo abstinence)",0,2)),"") | BA17: =IFERROR(IF(AZ17="","",IF(AZ17="None",0,IF(AZ17="One stable condition",1,2))),"") | BC17: =IFERROR(IF(BB17="Y",2,0),"") -> 0 | BD17: =IFERROR(SUM(AW17,AY17,BA17,BC17),"") -> 0 | BF17: =IFERROR(IF(BE17="","",IF(BE17="Ambulatory",0,IF(BE17="Wheelchair w/ cushions",1,IF(BE17="Bedbound w/ offloading mattress",2,3)))),"") | BH17: =IFERROR(IF(BG17="","",IF(BG17="Reliable 24/7 care",0,IF(BG17="Some support — inconsistent",2,0))),"") | BI17: =IFERROR(SUM(BF17,BH17),"") -> 0 | BJ17: =IFERROR(IF(COUNTA(AF17,AU17,BD17,BI17)=0,"",SUM(AF17,AU17,BD17,BI17)),"") -> 0 | BK17: =IFERROR(IF(BJ17="","",IF(BJ17<6,"LOW RISK",IF(BJ17<13,"MODERATE RISK",IF(BJ17<20,"HIGH RISK","NOT AN IDEAL CANDIDATE")))),"") -> LOW RISK | BL17: =IFERROR(_xlfn.SINGLE(_xlfn.TEXTJOIN(", ", TRUE(), IF(V17 = "<2.5 g/dL (Abs CI)", "Albumin CI", ""), IF(AB17 = ">2.0 or Sepsis (Abs CI)", "PCT CI", ""), IF(BG17 = "No support (Functional CI)", "Functional CI", ""))), "") | BU17: =IFERROR(IF(BT17="","",IF(BT17<6,"LOW RISK",IF(BT17<13,"MODERATE RISK",IF(BT17<20,"HIGH RISK","NOT AN IDEAL CANDIDATE")))),"") | CC17: =IFERROR(IF(COUNTA(BV17:CB17)=0,"",IF(COUNTIF(BV17:CB17,"Y")>0,"YES — EVENT","NO event")),"")
T18: =IF(COUNTIF(K18:S18,"Y")>0,"STOP — ABS CI PRESENT","✓ Clear to Score") -> ✓ Clear to Score | W18: =IFERROR(IF(V18="","",IF(V18="≥3.5 g/dL",0,IF(V18="3.0-3.49 g/dL",1,IF(V18="2.5-2.99 g/dL",3,0)))),"") | Y18: =IFERROR(IF(X18="","",IF(X18="≥18 mg/dL",0,IF(X18="12-17.9 mg/dL",1,2))),"") | AA18: =IFERROR(IF(Z18="","",IF(ISNUMBER(SEARCH("Normal",Z18)),0,IF(ISNUMBER(SEARCH("Borderline",Z18)),1,3))),"") | AC18: =IFERROR(IF(U18="N",0,IF(AB18="","",IF(AB18="0.5-2.0 ng/mL",1,0))),"") | AE18: =IFERROR(IF(U18="N",0,IF(AD18="Y",1,0)),"") -> 0 | AF18: =IFERROR(SUM(W18,Y18,AA18,AC18,AE18),"") -> 0 | AH18: =IFERROR(IF(AG18="","",IF(AG18="Ischial",3,IF(AG18="Multiple Sites",1,0))),"") | AJ18: =IFERROR(IF(AI18="","",IF(AI18="<50 cm²",0,IF(AI18="50-100 cm²",1,2))),"") | AL18: =IFERROR(IF(AK18="","",IF(AK18="None",0,IF(AK18="Chronic (>4wk + sequestrum/sinus)",1,3))),"") | AN18: =IFERROR(IF(AM18="","",IF(AM18="None",0,IF(AM18="1 prior flap",2,3))),"") | AP18: =IFERROR(IF(AO18="","",IF(AO18="None",0,IF(AO18="Intermittent (not daily)",1,2))),"") | AR18: =IFERROR(IF(OR(AG18="Lower Extremity",AG18="Multiple Sites"),IF(AQ18="Y",1,0),0),"") -> 0 | AT18: =IFERROR(IF(AS18="Y",1,0),"") -> 0 | AU18: =IFERROR(SUM(AH18,AJ18,AL18,AN18,AP18,AR18,AT18),"") -> 0 | AW18: =IFERROR(IF(AV18="","",IF(AV18="No diabetes / HbA1c <7.0%",0,IF(AV18="HbA1c 7.0-7.9%",1,2))),"") | AY18: =IFERROR(IF(AX18="","",IF(AX18="Never / Former (>6mo abstinence)",0,2)),"") | BA18: =IFERROR(IF(AZ18="","",IF(AZ18="None",0,IF(AZ18="One stable condition",1,2))),"") | BC18: =IFERROR(IF(BB18="Y",2,0),"") -> 0 | BD18: =IFERROR(SUM(AW18,AY18,BA18,BC18),"") -> 0 | BF18: =IFERROR(IF(BE18="","",IF(BE18="Ambulatory",0,IF(BE18="Wheelchair w/ cushions",1,IF(BE18="Bedbound w/ offloading mattress",2,3)))),"") | BH18: =IFERROR(IF(BG18="","",IF(BG18="Reliable 24/7 care",0,IF(BG18="Some support — inconsistent",2,0))),"") | BI18: =IFERROR(SUM(BF18,BH18),"") -> 0 | BJ18: =IFERROR(IF(COUNTA(AF18,AU18,BD18,BI18)=0,"",SUM(AF18,AU18,BD18,BI18)),"") -> 0 | BK18: =IFERROR(IF(BJ18="","",IF(BJ18<6,"LOW RISK",IF(BJ18<13,"MODERATE RISK",IF(BJ18<20,"HIGH RISK","NOT AN IDEAL CANDIDATE")))),"") -> LOW RISK | BL18: =IFERROR(_xlfn.SINGLE(_xlfn.TEXTJOIN(", ", TRUE(), IF(V18 = "<2.5 g/dL (Abs CI)", "Albumin CI", ""), IF(AB18 = ">2.0 or Sepsis (Abs CI)", "PCT CI", ""), IF(BG18 = "No support (Functional CI)", "Functional CI", ""))), "") | BU18: =IFERROR(IF(BT18="","",IF(BT18<6,"LOW RISK",IF(BT18<13,"MODERATE RISK",IF(BT18<20,"HIGH RISK","NOT AN IDEAL CANDIDATE")))),"") | CC18: =IFERROR(IF(COUNTA(BV18:CB18)=0,"",IF(COUNTIF(BV18:CB18,"Y")>0,"YES — EVENT","NO event")),"")
T19: =IF(COUNTIF(K19:S19,"Y")>0,"STOP — ABS CI PRESENT","✓ Clear to Score") -> ✓ Clear to Score | W19: =IFERROR(IF(V19="","",IF(V19="≥3.5 g/dL",0,IF(V19="3.0-3.49 g/dL",1,IF(V19="2.5-2.99 g/dL",3,0)))),"") | Y19: =IFERROR(IF(X19="","",IF(X19="≥18 mg/dL",0,IF(X19="12-17.9 mg/dL",1,2))),"") | AA19: =IFERROR(IF(Z19="","",IF(ISNUMBER(SEARCH("Normal",Z19)),0,IF(ISNUMBER(SEARCH("Borderline",Z19)),1,3))),"") | AC19: =IFERROR(IF(U19="N",0,IF(AB19="","",IF(AB19="0.5-2.0 ng/mL",1,0))),"") | AE19: =IFERROR(IF(U19="N",0,IF(AD19="Y",1,0)),"") -> 0 | AF19: =IFERROR(SUM(W19,Y19,AA19,AC19,AE19),"") -> 0 | AH19: =IFERROR(IF(AG19="","",IF(AG19="Ischial",3,IF(AG19="Multiple Sites",1,0))),"") | AJ19: =IFERROR(IF(AI19="","",IF(AI19="<50 cm²",0,IF(AI19="50-100 cm²",1,2))),"") | AL19: =IFERROR(IF(AK19="","",IF(AK19="None",0,IF(AK19="Chronic (>4wk + sequestrum/sinus)",1,3))),"") | AN19: =IFERROR(IF(AM19="","",IF(AM19="None",0,IF(AM19="1 prior flap",2,3))),"") | AP19: =IFERROR(IF(AO19="","",IF(AO19="None",0,IF(AO19="Intermittent (not daily)",1,2))),"") | AR19: =IFERROR(IF(OR(AG19="Lower Extremity",AG19="Multiple Sites"),IF(AQ19="Y",1,0),0),"") -> 0 | AT19: =IFERROR(IF(AS19="Y",1,0),"") -> 0 | AU19: =IFERROR(SUM(AH19,AJ19,AL19,AN19,AP19,AR19,AT19),"") -> 0 | AW19: =IFERROR(IF(AV19="","",IF(AV19="No diabetes / HbA1c <7.0%",0,IF(AV19="HbA1c 7.0-7.9%",1,2))),"") | AY19: =IFERROR(IF(AX19="","",IF(AX19="Never / Former (>6mo abstinence)",0,2)),"") | BA19: =IFERROR(IF(AZ19="","",IF(AZ19="None",0,IF(AZ19="One stable condition",1,2))),"") | BC19: =IFERROR(IF(BB19="Y",2,0),"") -> 0 | BD19: =IFERROR(SUM(AW19,AY19,BA19,BC19),"") -> 0 | BF19: =IFERROR(IF(BE19="","",IF(BE19="Ambulatory",0,IF(BE19="Wheelchair w/ cushions",1,IF(BE19="Bedbound w/ offloading mattress",2,3)))),"") | BH19: =IFERROR(IF(BG19="","",IF(BG19="Reliable 24/7 care",0,IF(BG19="Some support — inconsistent",2,0))),"") | BI19: =IFERROR(SUM(BF19,BH19),"") -> 0 | BJ19: =IFERROR(IF(COUNTA(AF19,AU19,BD19,BI19)=0,"",SUM(AF19,AU19,BD19,BI19)),"") -> 0 | BK19: =IFERROR(IF(BJ19="","",IF(BJ19<6,"LOW RISK",IF(BJ19<13,"MODERATE RISK",IF(BJ19<20,"HIGH RISK","NOT AN IDEAL CANDIDATE")))),"") -> LOW RISK | BL19: =IFERROR(_xlfn.SINGLE(_xlfn.TEXTJOIN(", ", TRUE(), IF(V19 = "<2.5 g/dL (Abs CI)", "Albumin CI", ""), IF(AB19 = ">2.0 or Sepsis (Abs CI)", "PCT CI", ""), IF(BG19 = "No support (Functional CI)", "Functional CI", ""))), "") | BU19: =IFERROR(IF(BT19="","",IF(BT19<6,"LOW RISK",IF(BT19<13,"MODERATE RISK",IF(BT19<20,"HIGH RISK","NOT AN IDEAL CANDIDATE")))),"") | CC19: =IFERROR(IF(COUNTA(BV19:CB19)=0,"",IF(COUNTIF(BV19:CB19,"Y")>0,"YES — EVENT","NO event")),"")
T20: =IF(COUNTIF(K20:S20,"Y")>0,"STOP — ABS CI PRESENT","✓ Clear to Score") -> ✓ Clear to Score | W20: =IFERROR(IF(V20="","",IF(V20="≥3.5 g/dL",0,IF(V20="3.0-3.49 g/dL",1,IF(V20="2.5-2.99 g/dL",3,0)))),"") | Y20: =IFERROR(IF(X20="","",IF(X20="≥18 mg/dL",0,IF(X20="12-17.9 mg/dL",1,2))),"") | AA20: =IFERROR(IF(Z20="","",IF(ISNUMBER(SEARCH("Normal",Z20)),0,IF(ISNUMBER(SEARCH("Borderline",Z20)),1,3))),"") | AC20: =IFERROR(IF(U20="N",0,IF(AB20="","",IF(AB20="0.5-2.0 ng/mL",1,0))),"") | AE20: =IFERROR(IF(U20="N",0,IF(AD20="Y",1,0)),"") -> 0 | AF20: =IFERROR(SUM(W20,Y20,AA20,AC20,AE20),"") -> 0 | AH20: =IFERROR(IF(AG20="","",IF(AG20="Ischial",3,IF(AG20="Multiple Sites",1,0))),"") | AJ20: =IFERROR(IF(AI20="","",IF(AI20="<50 cm²",0,IF(AI20="50-100 cm²",1,2))),"") | AL20: =IFERROR(IF(AK20="","",IF(AK20="None",0,IF(AK20="Chronic (>4wk + sequestrum/sinus)",1,3))),"") | AN20: =IFERROR(IF(AM20="","",IF(AM20="None",0,IF(AM20="1 prior flap",2,3))),"") | AP20: =IFERROR(IF(AO20="","",IF(AO20="None",0,IF(AO20="Intermittent (not daily)",1,2))),"") | AR20: =IFERROR(IF(OR(AG20="Lower Extremity",AG20="Multiple Sites"),IF(AQ20="Y",1,0),0),"") -> 0 | AT20: =IFERROR(IF(AS20="Y",1,0),"") -> 0 | AU20: =IFERROR(SUM(AH20,AJ20,AL20,AN20,AP20,AR20,AT20),"") -> 0 | AW20: =IFERROR(IF(AV20="","",IF(AV20="No diabetes / HbA1c <7.0%",0,IF(AV20="HbA1c 7.0-7.9%",1,2))),"") | AY20: =IFERROR(IF(AX20="","",IF(AX20="Never / Former (>6mo abstinence)",0,2)),"") | BA20: =IFERROR(IF(AZ20="","",IF(AZ20="None",0,IF(AZ20="One stable condition",1,2))),"") | BC20: =IFERROR(IF(BB20="Y",2,0),"") -> 0 | BD20: =IFERROR(SUM(AW20,AY20,BA20,BC20),"") -> 0 | BF20: =IFERROR(IF(BE20="","",IF(BE20="Ambulatory",0,IF(BE20="Wheelchair w/ cushions",1,IF(BE20="Bedbound w/ offloading mattress",2,3)))),"") | BH20: =IFERROR(IF(BG20="","",IF(BG20="Reliable 24/7 care",0,IF(BG20="Some support — inconsistent",2,0))),"") | BI20: =IFERROR(SUM(BF20,BH20),"") -> 0 | BJ20: =IFERROR(IF(COUNTA(AF20,AU20,BD20,BI20)=0,"",SUM(AF20,AU20,BD20,BI20)),"") -> 0 | BK20: =IFERROR(IF(BJ20="","",IF(BJ20<6,"LOW RISK",IF(BJ20<13,"MODERATE RISK",IF(BJ20<20,"HIGH RISK","NOT AN IDEAL CANDIDATE")))),"") -> LOW RISK | BL20: =IFERROR(_xlfn.SINGLE(_xlfn.TEXTJOIN(", ", TRUE(), IF(V20 = "<2.5 g/dL (Abs CI)", "Albumin CI", ""), IF(AB20 = ">2.0 or Sepsis (Abs CI)", "PCT CI", ""), IF(BG20 = "No support (Functional CI)", "Functional CI", ""))), "") | BU20: =IFERROR(IF(BT20="","",IF(BT20<6,"LOW RISK",IF(BT20<13,"MODERATE RISK",IF(BT20<20,"HIGH RISK","NOT AN IDEAL CANDIDATE")))),"") | CC20: =IFERROR(IF(COUNTA(BV20:CB20)=0,"",IF(COUNTIF(BV20:CB20,"Y")>0,"YES — EVENT","NO event")),"")
T21: =IF(COUNTIF(K21:S21,"Y")>0,"STOP — ABS CI PRESENT","✓ Clear to Score") -> ✓ Clear to Score | W21: =IFERROR(IF(V21="","",IF(V21="≥3.5 g/dL",0,IF(V21="3.0-3.49 g/dL",1,IF(V21="2.5-2.99 g/dL",3,0)))),"") | Y21: =IFERROR(IF(X21="","",IF(X21="≥18 mg/dL",0,IF(X21="12-17.9 mg/dL",1,2))),"") | AA21: =IFERROR(IF(Z21="","",IF(ISNUMBER(SEARCH("Normal",Z21)),0,IF(ISNUMBER(SEARCH("Borderline",Z21)),1,3))),"") | AC21: =IFERROR(IF(U21="N",0,IF(AB21="","",IF(AB21="0.5-2.0 ng/mL",1,0))),"") | AE21: =IFERROR(IF(U21="N",0,IF(AD21="Y",1,0)),"") -> 0 | AF21: =IFERROR(SUM(W21,Y21,AA21,AC21,AE21),"") -> 0 | AH21: =IFERROR(IF(AG21="","",IF(AG21="Ischial",3,IF(AG21="Multiple Sites",1,0))),"") | AJ21: =IFERROR(IF(AI21="","",IF(AI21="<50 cm²",0,IF(AI21="50-100 cm²",1,2))),"") | AL21: =IFERROR(IF(AK21="","",IF(AK21="None",0,IF(AK21="Chronic (>4wk + sequestrum/sinus)",1,3))),"") | AN21: =IFERROR(IF(AM21="","",IF(AM21="None",0,IF(AM21="1 prior flap",2,3))),"") | AP21: =IFERROR(IF(AO21="","",IF(AO21="None",0,IF(AO21="Intermittent (not daily)",1,2))),"") | AR21: =IFERROR(IF(OR(AG21="Lower Extremity",AG21="Multiple Sites"),IF(AQ21="Y",1,0),0),"") -> 0 | AT21: =IFERROR(IF(AS21="Y",1,0),"") -> 0 | AU21: =IFERROR(SUM(AH21,AJ21,AL21,AN21,AP21,AR21,AT21),"") -> 0 | AW21: =IFERROR(IF(AV21="","",IF(AV21="No diabetes / HbA1c <7.0%",0,IF(AV21="HbA1c 7.0-7.9%",1,2))),"") | AY21: =IFERROR(IF(AX21="","",IF(AX21="Never / Former (>6mo abstinence)",0,2)),"") | BA21: =IFERROR(IF(AZ21="","",IF(AZ21="None",0,IF(AZ21="One stable condition",1,2))),"") | BC21: =IFERROR(IF(BB21="Y",2,0),"") -> 0 | BD21: =IFERROR(SUM(AW21,AY21,BA21,BC21),"") -> 0 | BF21: =IFERROR(IF(BE21="","",IF(BE21="Ambulatory",0,IF(BE21="Wheelchair w/ cushions",1,IF(BE21="Bedbound w/ offloading mattress",2,3)))),"") | BH21: =IFERROR(IF(BG21="","",IF(BG21="Reliable 24/7 care",0,IF(BG21="Some support — inconsistent",2,0))),"") | BI21: =IFERROR(SUM(BF21,BH21),"") -> 0 | BJ21: =IFERROR(IF(COUNTA(AF21,AU21,BD21,BI21)=0,"",SUM(AF21,AU21,BD21,BI21)),"") -> 0 | BK21: =IFERROR(IF(BJ21="","",IF(BJ21<6,"LOW RISK",IF(BJ21<13,"MODERATE RISK",IF(BJ21<20,"HIGH RISK","NOT AN IDEAL CANDIDATE")))),"") -> LOW RISK | BL21: =IFERROR(_xlfn.SINGLE(_xlfn.TEXTJOIN(", ", TRUE(), IF(V21 = "<2.5 g/dL (Abs CI)", "Albumin CI", ""), IF(AB21 = ">2.0 or Sepsis (Abs CI)", "PCT CI", ""), IF(BG21 = "No support (Functional CI)", "Functional CI", ""))), "") | BU21: =IFERROR(IF(BT21="","",IF(BT21<6,"LOW RISK",IF(BT21<13,"MODERATE RISK",IF(BT21<20,"HIGH RISK","NOT AN IDEAL CANDIDATE")))),"") | CC21: =IFERROR(IF(COUNTA(BV21:CB21)=0,"",IF(COUNTIF(BV21:CB21,"Y")>0,"YES — EVENT","NO event")),"")
